<!-- 需求:设置机器人底盘,并添加摄像头 -->
<robot name="mycar">
    <link name="base_footprint">
        <visual>
            <geometry>
                <box size="0.001 0.001 0.001" />
            </geometry>
        </visual>
    </link>
    <!-- 1.底盘link -->
    <link name="base_link">
        <visual>
            <geometry>
                <box size="0.3 0.2 0.1" />
            </geometry>
            <origin xyz="0 0 0" rpy="0 0 0"/>
            <material name="car_color">
                <color rgba="0.8 0.5 0 0.5"/>
            </material>
        </visual>
    </link>
    <!-- 2.摄像头 -->
    <link name="camera">
        <visual>
            <geometry>
                <box size="0.02 0.05 0.05" />
            </geometry>
            <origin xyz="0 0 0.025" rpy="0 0 0"/>
            <material name="camera_color">
                <color rgba="0 0 1 0.5"/>
            </material>
        </visual>
    </link>
    <!-- 关联 base_footprint 与 base_link -->
    <joint name="link2footprint" type="fixed">
        <parent link="base_footprint"/>
        <child link="base_link"/>
        <origin xyz="0 0 0.05" rpy="0 0 0"/>
    </joint>
    
    <!-- 3.关节 -->
    <joint name="camera2base" type="continuous">
        <!-- 父级 -->
        <parent link="base_link"/>
        <!-- 子级 -->
        <child link="camera"/>
        <!-- 关节原点 -->
        <origin xyz="0.12 0 0.05" rpy="0 0 0"/>
        <!-- 关节轴 -->
        <axis xyz="0 0 1"/>
    </joint>
</robot>
